<?xml version="1.0" ?>
<!-- =================================================================================== -->
<!-- |    This document was autogenerated by xacro from robot_arm.urdf.xacro           | -->
<!-- |    EDITING THIS FILE BY HAND IS NOT RECOMMENDED                                 | -->
<!-- =================================================================================== -->
<robot name="realistic_arm">
  <!-- COLORS -->
  <material name="dark_grey">
    <color rgba="0.2 0.2 0.2 1"/>
  </material>
  <material name="dark_blue">
    <color rgba="0.1 0.2 0.4 1"/>
  </material>
  <material name="light_grey">
    <color rgba="0.7 0.7 0.7 1"/>
  </material>
  <material name="bright_green">
    <color rgba="0.0 0.8 0.0 1"/>
  </material>
  <!-- WORLD & BASE -->
  <link name="world"/>
  <joint name="world_joint" type="fixed">
    <parent link="world"/>
    <child link="base_link"/>
  </joint>
  <link name="base_link">
    <visual>
      <geometry>
        <cylinder length="0.12" radius="0.12"/>
      </geometry>
      <origin rpy="0 0 0" xyz="0 0 0.06"/>
      <material name="dark_grey"/>
    </visual>
    <collision>
      <geometry>
        <cylinder length="0.12" radius="0.12"/>
      </geometry>
      <origin rpy="0 0 0" xyz="0 0 0.06"/>
    </collision>
    <inertial>
      <mass value="10.0"/>
      <origin rpy="0 0 0" xyz="0 0 0.06"/>
      <inertia ixx="0.047999999999999994" ixy="0" ixz="0" iyy="0.047999999999999994" iyz="0" izz="0.072"/>
    </inertial>
  </link>
  <!-- ============ JOINT 1: WAIST ROTATION (Z-AXIS) ============ -->
  <!-- SAFE LIMITS: -180° to +180° (full rotation, but controlled) -->
  <joint name="shoulder_pan_joint" type="revolute">
    <parent link="base_link"/>
    <child link="shoulder_link"/>
    <origin rpy="0 0 0" xyz="0 0 0.12"/>
    <axis xyz="0 0 1"/>
    <limit effort="150" lower="-3.14159" upper="3.14159" velocity="1.0"/>
    <dynamics damping="0.5" friction="0.5"/>
  </joint>
  <link name="shoulder_link">
    <visual>
      <geometry>
        <cylinder length="0.15" radius="0.08"/>
      </geometry>
      <origin rpy="0 0 0" xyz="0 0 0.075"/>
      <material name="dark_blue"/>
    </visual>
    <visual>
      <geometry>
        <cylinder length="0.05" radius="0.065"/>
      </geometry>
      <origin rpy="0 0 0" xyz="0 0 0.15"/>
      <material name="bright_green"/>
    </visual>
    <collision>
      <geometry>
        <cylinder length="0.15" radius="0.08"/>
      </geometry>
      <origin rpy="0 0 0" xyz="0 0 0.075"/>
    </collision>
    <inertial>
      <mass value="4.0"/>
      <origin rpy="0 0 0" xyz="0 0 0.075"/>
      <inertia ixx="0.013900000000000001" ixy="0" ixz="0" iyy="0.013900000000000001" iyz="0" izz="0.0128"/>
    </inertial>
  </link>
  <!-- ============ JOINT 2: SHOULDER LIFT (Y-AXIS) ============ -->
  <!-- SAFE LIMITS: -90° to +90° (up and down, but not backwards) -->
  <joint name="shoulder_lift_joint" type="revolute">
    <parent link="shoulder_link"/>
    <child link="upper_arm_link"/>
    <origin rpy="0 0 0" xyz="0 0 0.15"/>
    <axis xyz="0 1 0"/>
    <limit effort="150" lower="-1.5708" upper="1.5708" velocity="0.8"/>
    <dynamics damping="0.5" friction="0.5"/>
  </joint>
  <link name="upper_arm_link">
    <visual>
      <geometry>
        <box size="0.09 0.09 0.65"/>
      </geometry>
      <origin rpy="0 0 0" xyz="0 0 0.325"/>
      <material name="light_grey"/>
    </visual>
    <visual>
      <geometry>
        <cylinder length="0.07" radius="0.06"/>
      </geometry>
      <origin rpy="0 0 0" xyz="0 0 0"/>
      <material name="dark_blue"/>
    </visual>
    <visual>
      <geometry>
        <cylinder length="0.07" radius="0.06"/>
      </geometry>
      <origin rpy="0 0 0" xyz="0 0 0.65"/>
      <material name="dark_blue"/>
    </visual>
    <collision>
      <geometry>
        <box size="0.09 0.09 0.65"/>
      </geometry>
      <origin rpy="0 0 0" xyz="0 0 0.325"/>
    </collision>
    <inertial>
      <mass value="3.5"/>
      <origin rpy="0 0 0" xyz="0 0 0.325"/>
      <inertia ixx="0.12559166666666668" ixy="0" ixz="0" iyy="0.12559166666666668" iyz="0" izz="0.004725"/>
    </inertial>
  </link>
  <!-- ============ JOINT 3: ELBOW (Y-AXIS) ============ -->
  <!-- SAFE LIMITS: -90° to +90° (flexion/extension only) -->
  <joint name="elbow_joint" type="revolute">
    <parent link="upper_arm_link"/>
    <child link="forearm_link"/>
    <origin rpy="0 0 0" xyz="0 0 0.65"/>
    <axis xyz="0 1 0"/>
    <limit effort="100" lower="-1.5708" upper="1.5708" velocity="0.8"/>
    <dynamics damping="0.5" friction="0.5"/>
  </joint>
  <link name="forearm_link">
    <visual>
      <geometry>
        <box size="0.08 0.08 0.55"/>
      </geometry>
      <origin rpy="0 0 0" xyz="0 0 0.275"/>
      <material name="light_grey"/>
    </visual>
    <visual>
      <geometry>
        <cylinder length="0.06" radius="0.055"/>
      </geometry>
      <origin rpy="0 0 0" xyz="0 0 0"/>
      <material name="dark_blue"/>
    </visual>
    <visual>
      <geometry>
        <cylinder length="0.06" radius="0.055"/>
      </geometry>
      <origin rpy="0 0 0" xyz="0 0 0.55"/>
      <material name="dark_blue"/>
    </visual>
    <collision>
      <geometry>
        <box size="0.08 0.08 0.55"/>
      </geometry>
      <origin rpy="0 0 0" xyz="0 0 0.275"/>
    </collision>
    <inertial>
      <mass value="2.5"/>
      <origin rpy="0 0 0" xyz="0 0 0.275"/>
      <inertia ixx="0.06435416666666667" ixy="0" ixz="0" iyy="0.06435416666666667" iyz="0" izz="0.0026666666666666666"/>
    </inertial>
  </link>
  <!-- ============ JOINT 4: WRIST 1 ROTATION (Z-AXIS) ============ -->
  <!-- SAFE LIMITS: -180° to +180° (full twist) -->
  <joint name="wrist_1_joint" type="revolute">
    <parent link="forearm_link"/>
    <child link="wrist_1_link"/>
    <origin rpy="0 0 0" xyz="0 0 0.55"/>
    <axis xyz="0 0 1"/>
    <limit effort="75" lower="-3.14159" upper="3.14159" velocity="1.5"/>
    <dynamics damping="0.3" friction="0.3"/>
  </joint>
  <link name="wrist_1_link">
    <visual>
      <geometry>
        <cylinder length="0.1" radius="0.05"/>
      </geometry>
      <origin rpy="0 0 0" xyz="0 0 0.05"/>
      <material name="dark_blue"/>
    </visual>
    <visual>
      <geometry>
        <sphere radius="0.045"/>
      </geometry>
      <origin rpy="0 0 0" xyz="0 0 0.1"/>
      <material name="bright_green"/>
    </visual>
    <collision>
      <geometry>
        <cylinder length="0.1" radius="0.05"/>
      </geometry>
      <origin rpy="0 0 0" xyz="0 0 0.05"/>
    </collision>
    <inertial>
      <mass value="1.5"/>
      <origin rpy="0 0 0" xyz="0 0 0.05"/>
      <inertia ixx="0.0021875" ixy="0" ixz="0" iyy="0.0021875" iyz="0" izz="0.0018750000000000004"/>
    </inertial>
  </link>
  <!-- ============ JOINT 5: WRIST 2 TILT (Y-AXIS) ============ -->
  <!-- SAFE LIMITS: -90° to +90° (tool tilt) -->
  <joint name="wrist_2_joint" type="revolute">
    <parent link="wrist_1_link"/>
    <child link="wrist_2_link"/>
    <origin rpy="0 0 0" xyz="0 0 0.1"/>
    <axis xyz="0 1 0"/>
    <limit effort="50" lower="-1.5708" upper="1.5708" velocity="1.5"/>
    <dynamics damping="0.3" friction="0.3"/>
  </joint>
  <link name="wrist_2_link">
    <visual>
      <geometry>
        <box size="0.06 0.06 0.25"/>
      </geometry>
      <origin rpy="0 0 0" xyz="0 0 0.125"/>
      <material name="light_grey"/>
    </visual>
    <visual>
      <geometry>
        <sphere radius="0.04"/>
      </geometry>
      <origin rpy="0 0 0" xyz="0 0 0"/>
      <material name="dark_blue"/>
    </visual>
    <visual>
      <geometry>
        <sphere radius="0.04"/>
      </geometry>
      <origin rpy="0 0 0" xyz="0 0 0.25"/>
      <material name="dark_blue"/>
    </visual>
    <collision>
      <geometry>
        <box size="0.06 0.06 0.25"/>
      </geometry>
      <origin rpy="0 0 0" xyz="0 0 0.125"/>
    </collision>
    <inertial>
      <mass value="1.0"/>
      <origin rpy="0 0 0" xyz="0 0 0.125"/>
      <inertia ixx="0.005508333333333334" ixy="0" ixz="0" iyy="0.005508333333333334" iyz="0" izz="0.0006"/>
    </inertial>
  </link>
  <!-- ============ JOINT 6: WRIST 3 ROTATION (Z-AXIS) ============ -->
  <!-- SAFE LIMITS: -180° to +180° (end-effector twist) -->
  <joint name="wrist_3_joint" type="revolute">
    <parent link="wrist_2_link"/>
    <child link="tool_link"/>
    <origin rpy="0 0 0" xyz="0 0 0.25"/>
    <axis xyz="0 0 1"/>
    <limit effort="40" lower="-3.14159" upper="3.14159" velocity="2.0"/>
    <dynamics damping="0.2" friction="0.2"/>
  </joint>
  <link name="tool_link">
    <visual>
      <geometry>
        <cylinder length="0.08" radius="0.035"/>
      </geometry>
      <origin rpy="0 0 0" xyz="0 0 0.04"/>
      <material name="bright_green"/>
    </visual>
    <visual>
      <geometry>
        <sphere radius="0.04"/>
      </geometry>
      <origin rpy="0 0 0" xyz="0 0 0.1"/>
      <material name="dark_blue"/>
    </visual>
    <collision>
      <geometry>
        <cylinder length="0.08" radius="0.035"/>
      </geometry>
      <origin rpy="0 0 0" xyz="0 0 0.04"/>
    </collision>
    <inertial>
      <mass value="0.5"/>
      <origin rpy="0 0 0" xyz="0 0 0.04"/>
      <inertia ixx="0.0004197916666666667" ixy="0" ixz="0" iyy="0.0004197916666666667" iyz="0" izz="0.00030625000000000004"/>
    </inertial>
  </link>
</robot>
